Workbook

Sheet Despesas
A1: 2020
A2: Saídas | B2: Venc. | C2: Jan | D2: Fev | E2: Mar | F2: Abr | G2: Mai | H2: Jun | I2: Jul | J2: Ago | K2: Set | L2: Out | M2: Nov | N2: Dez | O2: Total
A3: Aluguel | B3: 8 | C3: 10 | D3: 10 | E3: 10 | F3: 10 | G3: 10 | H3: 10 | I3: 10 | J3: 10 | K3: 10 | L3: 10 | M3: 10 | N3: 10 | O3: =SUM(C3:N3) -> 120 | Q3: =CONCATENATE(A3," - ",S3," %") -> Aluguel - 60 % | R3: =O3 -> 120 | S3: =ROUND(O3/$O$24*100,2) -> 60
A4: Celular | B4: 12 | C4: 5 | D4: 5 | E4: 5 | F4: 5 | G4: 5 | H4: 5 | I4: 5 | J4: 5 | K4: 5 | L4: 5 | M4: 5 | N4: 5 | O4: =SUM(C4:N4) -> 60 | Q4: =CONCATENATE(A4," - ",S4," %") -> Celular - 30 % | R4: =O4 -> 60 | S4: =ROUND(O4/$O$24*100,2) -> 30
A5: Transporte | B5: 12 | C5: =0 -> 0 | D5: =0 -> 0 | E5: =0 -> 0 | F5: =0 -> 0 | G5: =0 -> 0 | H5: =0 -> 0 | I5: =0 -> 0 | J5: =0 -> 0 | ... N5: =0 -> 0 | O5: =SUM(C5:N5) -> 0 | Q5: =CONCATENATE(A5," - ",S5," %") -> Transporte - 0 % | R5: =O5 -> 0 | S5: =ROUND(O5/$O$24*100,2) -> 0
A6: Luz | B6: 8 | C6: 5 | D6: 5 | E6: 5 | F6: 5 | G6: 5 | H6: 5 | I6: 5 | J6: 5 | K6: 5 | L6: 5 | M6: 5 | N6: 5 | O6: =SUM(C6:N6) -> 60 | Q6: =CONCATENATE(A6," - ",S6," %") -> Luz - 30 % | R6: =O6 -> 60 | S6: =ROUND(O6/$O$24*100,2) -> 30
A7: Internet | B7: 8 | C7: 5 | D7: 5 | E7: 5 | F7: 5 | G7: 5 | H7: 5 | I7: 5 | J7: 5 | K7: 5 | L7: 5 | M7: 5 | N7: 5 | O7: =SUM(C7:N7) -> 60 | Q7: =CONCATENATE(A7," - ",S7," %") -> Internet - 30 % | R7: =O7 -> 60 | S7: =ROUND(O7/$O$24*100,2) -> 30
A8: {=RIGHT(CELL("nome.arquivo",'Cartão 1'!B1:Y1), LEN(CELL("nome.arquivo",'Cartão 1'!B1:Y1))- SEARCH("]",CELL("nome.arquivo",'Cartão 1'!B1:Y1)))} -> Cartão 1 | B8: 8 | C8: =SUM('Cartão 1'!C2:C101) -> 0 | D8: =SUM('Cartão 1'!E2:E101) -> 0 | E8: =SUM('Cartão 1'!G2:G101) -> 0 | F8: =SUM('Cartão 1'!I2:I101) -> 0 | G8: =SUM('Cartão 1'!K2:K101) -> 0 | H8: =SUM('Cartão 1'!M2:M101) -> 0 | I8: =SUM('Cartão 1'!O2:O101) -> 0 | J8: =SUM('Cartão 1'!Q2:Q101) -> 0 | K8: =SUM('Cartão 1'!S2:S101) -> 0 | L8: =SUM('Cartão 1'!U2:U101) -> 0 | M8: =SUM('Cartão 1'!W2:W101) -> 0 | N8: =SUM('Cartão 1'!Y2:Y101) -> 0 | O8: =SUM(C8:N8) -> 0 | Q8: =CONCATENATE(A8," - ",S8," %") -> Cartão 1 - 0 % | R8: =O8 -> 0 | S8: =ROUND(O8/$O$24*100,2) -> 0
A9: {=RIGHT(CELL("nome.arquivo",'Cartão 2'!B1:Y1), LEN(CELL("nome.arquivo",'Cartão 2'!B1:Y1))- SEARCH("]",CELL("nome.arquivo",'Cartão 2'!B1:Y1)))} -> Cartão 2 | B9: 8 | C9: =SUM('Cartão 1'!C3:C102) -> 0 | D9: =SUM('Cartão 1'!E3:E102) -> 0 | E9: =SUM('Cartão 1'!G3:G102) -> 0 | F9: =SUM('Cartão 1'!I3:I102) -> 0 | G9: =SUM('Cartão 1'!K3:K102) -> 0 | H9: =SUM('Cartão 1'!M3:M102) -> 0 | I9: =SUM('Cartão 1'!O3:O102) -> 0 | J9: =SUM('Cartão 1'!Q3:Q102) -> 0 | K9: =SUM('Cartão 1'!S3:S102) -> 0 | L9: =SUM('Cartão 1'!U3:U102) -> 0 | M9: =SUM('Cartão 1'!W3:W102) -> 0 | N9: =SUM('Cartão 1'!Y3:Y102) -> 0 | O9: =SUM(C9:N9) -> 0 | Q9: =CONCATENATE(A9," - ",S9," %") -> Cartão 2 - 0 % | R9: =O9 -> 0 | S9: =ROUND(O9/$O$24*100,2) -> 0
A10: {=RIGHT(CELL("nome.arquivo",Gastos!B1:Y1), LEN(CELL("nome.arquivo",Gastos!B1:Y1))- SEARCH("]",CELL("nome.arquivo",Gastos!B1:Y1)))} -> Gastos | B10: 1 | C10: =SUM(Gastos!D3:D102) -> 0 | D10: =SUM(Gastos!G3:G102) -> 0 | E10: =SUM(Gastos!J3:J102) -> 0 | F10: =SUM(Gastos!M3:M102) -> 0 | G10: =SUM(Gastos!P3:P102) -> 0 | H10: =SUM(Gastos!S3:S102) -> 0 | I10: =SUM(Gastos!V3:V102) -> 0 | J10: =SUM(Gastos!Y3:Y102) -> 0 | K10: =SUM(Gastos!AB3:AB102) -> 0 | L10: =SUM(Gastos!AE3:AE102) -> 0 | M10: =SUM(Gastos!AH3:AH102) -> 0 | N10: =SUM(Gastos!AK3:AK102) -> 0 | O10: =SUM(C10:N10) -> 0 | Q10: =CONCATENATE(A10," - ",S10," %") -> Gastos - 0 % | R10: =O10 -> 0 | S10: =ROUND(O10/$O$24*100,2) -> 0
C11: =0 -> 0 | D11: =0 -> 0 | E11: =0 -> 0 | F11: =0 -> 0 | G11: =0 -> 0 | H11: =0 -> 0 | I11: =0 -> 0 | J11: =0 -> 0 | ... N11: =0 -> 0 | O11: =SUM(C11:N11) -> 0 | Q11: =CONCATENATE(A11," - ",S11," %") -> - 0 % | R11: =O11 -> 0 | S11: =ROUND(O11/$O$24*100,2) -> 0
C12: =0 -> 0 | D12: =0 -> 0 | E12: =0 -> 0 | F12: =0 -> 0 | G12: =0 -> 0 | H12: =0 -> 0 | I12: =0 -> 0 | J12: =0 -> 0 | ... N12: =0 -> 0 | O12: =SUM(C12:N12) -> 0 | Q12: =CONCATENATE(A12," - ",S12," %") -> - 0 % | R12: =O12 -> 0 | S12: =ROUND(O12/$O$24*100,2) -> 0
C13: =0 -> 0 | D13: =0 -> 0 | E13: =0 -> 0 | F13: =0 -> 0 | G13: =0 -> 0 | H13: =0 -> 0 | I13: =0 -> 0 | J13: =0 -> 0 | ... N13: =0 -> 0 | O13: =SUM(C13:N13) -> 0 | Q13: =CONCATENATE(A13," - ",S13," %") -> - 0 % | R13: =O13 -> 0 | S13: =ROUND(O13/$O$24*100,2) -> 0
C14: =0 -> 0 | D14: =0 -> 0 | E14: =0 -> 0 | F14: =0 -> 0 | G14: =0 -> 0 | H14: =0 -> 0 | I14: =0 -> 0 | J14: =0 -> 0 | ... N14: =0 -> 0 | O14: =SUM(C14:N14) -> 0 | Q14: =CONCATENATE(A14," - ",S14," %") -> - 0 % | R14: =O14 -> 0 | S14: =ROUND(O14/$O$24*100,2) -> 0
C15: =0 -> 0 | D15: =0 -> 0 | E15: =0 -> 0 | F15: =0 -> 0 | G15: =0 -> 0 | H15: =0 -> 0 | I15: =0 -> 0 | J15: =0 -> 0 | ... N15: =0 -> 0 | O15: =SUM(C15:N15) -> 0 | Q15: =CONCATENATE(A15," - ",S15," %") -> - 0 % | R15: =O15 -> 0 | S15: =ROUND(O15/$O$24*100,2) -> 0
C16: =0 -> 0 | D16: =0 -> 0 | E16: =0 -> 0 | F16: =0 -> 0 | G16: =0 -> 0 | H16: =0 -> 0 | I16: =0 -> 0 | J16: =0 -> 0 | ... N16: =0 -> 0 | O16: =SUM(C16:N16) -> 0 | Q16: =CONCATENATE(A16," - ",S16," %") -> - 0 % | R16: =O16 -> 0 | S16: =ROUND(O16/$O$24*100,2) -> 0
C17: =0 -> 0 | D17: =0 -> 0 | E17: =0 -> 0 | F17: =0 -> 0 | G17: =0 -> 0 | H17: =0 -> 0 | I17: =0 -> 0 | J17: =0 -> 0 | ... N17: =0 -> 0 | O17: =SUM(C17:N17) -> 0 | Q17: =CONCATENATE(A17," - ",S17," %") -> - 0 % | R17: =O17 -> 0 | S17: =ROUND(O17/$O$24*100,2) -> 0
C18: =0 -> 0 | D18: =0 -> 0 | E18: =0 -> 0 | F18: =0 -> 0 | G18: =0 -> 0 | H18: =0 -> 0 | I18: =0 -> 0 | J18: =0 -> 0 | ... N18: =0 -> 0 | O18: =SUM(C18:N18) -> 0 | Q18: =CONCATENATE(A18," - ",S18," %") -> - 0 % | R18: =O18 -> 0 | S18: =ROUND(O18/$O$24*100,2) -> 0
C19: =0 -> 0 | D19: =0 -> 0 | E19: =0 -> 0 | F19: =0 -> 0 | G19: =0 -> 0 | H19: =0 -> 0 | I19: =0 -> 0 | J19: =0 -> 0 | ... N19: =0 -> 0 | O19: =SUM(C19:N19) -> 0 | Q19: =CONCATENATE(A19," - ",S19," %") -> - 0 % | R19: =O19 -> 0 | S19: =ROUND(O19/$O$24*100,2) -> 0
C20: =0 -> 0 | D20: =0 -> 0 | E20: =0 -> 0 | F20: =0 -> 0 | G20: =0 -> 0 | H20: =0 -> 0 | I20: =0 -> 0 | J20: =0 -> 0 | ... N20: =0 -> 0 | O20: =SUM(C20:N20) -> 0 | Q20: =CONCATENATE(A20," - ",S20," %") -> - 0 % | R20: =O20 -> 0 | S20: =ROUND(O20/$O$24*100,2) -> 0
C21: =0 -> 0 | D21: =0 -> 0 | E21: =0 -> 0 | F21: =0 -> 0 | G21: =0 -> 0 | H21: =0 -> 0 | I21: =0 -> 0 | J21: =0 -> 0 | ... N21: =0 -> 0 | O21: =SUM(C21:N21) -> 0 | Q21: =CONCATENATE(A21," - ",S21," %") -> - 0 % | R21: =O21 -> 0 | S21: =ROUND(O21/$O$24*100,2) -> 0
A22: Poupança | B22: 1 | C22: =0 -> 0 | D22: =0 -> 0 | E22: =0 -> 0 | F22: =0 -> 0 | G22: =0 -> 0 | H22: =0 -> 0 | I22: =0 -> 0 | J22: =0 -> 0 | ... N22: =0 -> 0 | O22: =SUM(C22:N22) -> 0 | Q22: =CONCATENATE(A22," - ",S22," %") -> Poupança - 0 % | R22: =O22 -> 0 | S22: =ROUND(O22/$O$24*100,2) -> 0
A23: Gastos Até Hoje | C23: =IF(AND(YEAR(NOW()) = $A$1,MONTH(NOW()) >= 1), SUMIF($B$3:$B$22,"<=" & DAY(TODAY()),C3:C22), 0 ) -> 0 | D23: =IF(AND(YEAR(NOW()) = $A$1,MONTH(NOW()) >= 2), SUMIF($B$3:$B$22,"<=" & DAY(TODAY()),D3:D22), 0 ) -> 0 | E23: =IF(AND(YEAR(NOW()) = $A$1,MONTH(NOW()) >= 3), SUMIF($B$3:$B$22,"<=" & DAY(TODAY()),E3:E22), 0 ) -> 0 | F23: =IF(AND(YEAR(NOW()) = $A$1,MONTH(NOW()) >= 4), SUMIF($B$3:$B$22,"<=" & DAY(TODAY()),F3:F22), 0 ) -> 0 | G23: =IF(AND(YEAR(NOW()) = $A$1,MONTH(NOW()) >= 5), SUMIF($B$3:$B$22,"<=" & DAY(TODAY()),G3:G22), 0 ) -> 0 | H23: =IF(AND(YEAR(NOW()) = $A$1,MONTH(NOW()) >= 6), SUMIF($B$3:$B$22,"<=" & DAY(TODAY()),H3:H22), 0 ) -> 0 | I23: =IF(AND(YEAR(NOW()) = $A$1,MONTH(NOW()) >= 7), SUMIF($B$3:$B$22,"<=" & DAY(TODAY()),I3:I22), 0 ) -> 0 | J23: =IF(AND(YEAR(NOW()) = $A$1,MONTH(NOW()) >= 8), SUMIF($B$3:$B$22,"<=" & DAY(TODAY()),J3:J22), 0 ) -> 0 | K23: =IF(AND(YEAR(NOW()) = $A$1,MONTH(NOW()) >= 9), SUMIF($B$3:$B$22,"<=" & DAY(TODAY()),K3:K22), 0 ) -> 0 | L23: =IF(AND(YEAR(NOW()) = $A$1,MONTH(NOW()) >= 10), SUMIF($B$3:$B$22,"<=" & DAY(TODAY()),L3:L22), 0 ) -> 0 | M23: =IF(AND(YEAR(NOW()) = $A$1,MONTH(NOW()) >= 11), SUMIF($B$3:$B$22,"<=" & DAY(TODAY()),M3:M22), 0 ) -> 0 | N23: =IF(AND(YEAR(NOW()) = $A$1,MONTH(NOW()) >= 12), SUMIF($B$3:$B$22,"<=" & DAY(TODAY()),N3:N22), 0 ) -> 0 | O23: =SUM(C23:N23) -> 0 | Q23: =CONCATENATE(A23," - ",S23," %") -> Gastos Até Hoje - 0 % | R23: =O23 -> 0 | S23: =ROUND(O23/$O$24*100,2) -> 0
A24: Total | C24: =SUM(C3:C22) -> 25 | D24: =SUM(D3:D22) -> 25 | E24: =SUM(E3:E22) -> 25 | F24: =SUM(F3:F22) -> 25 | G24: =SUM(G3:G22) -> 25 | H24: =SUM(H3:H22) -> 25 | I24: =SUM(I3:I22) -> 25 | J24: =SUM(J3:J22) -> 25 | ... N24: =SUM(N3:N22) -> 25 | O24: =SUM(G24:N24) -> 200 | Q24: =A24 -> Total | R24: =O24 -> 200 | S24: =ROUND(O24/$O$24*100,2) -> 100
A26: Total de Cartões | C26: =SUM(C8:C9) -> 0 | D26: =SUM(D8:D9) -> 0 | E26: =SUM(E8:E9) -> 0 | F26: =SUM(F8:F9) -> 0 | G26: =SUM(G8:G9) -> 0 | H26: =SUM(H8:H9) -> 0 | I26: =SUM(I8:I9) -> 0 | J26: =SUM(J8:J9) -> 0 | ... N26: =SUM(N8:N9) -> 0
A28: Entradas | C28: Jan | D28: Fev | E28: Mar | F28: Abr | G28: Mai | H28: Jun | I28: Jul | J28: Ago | K28: Set | L28: Out | M28: Nov | N28: Dez | O28: Total
A29: Salário | B29: 5 | C29: 50 | D29: 50 | E29: 50 | F29: 50 | G29: 50 | H29: 50 | I29: 50 | J29: 50 | K29: 50 | L29: 50 | M29: 50 | N29: 50 | O29: =SUM(C29:N29) -> 600 | Q29: =CONCATENATE(A29," - ",S29," %") -> Salário - 100 % | R29: =O29 -> 600 | S29: =ROUND(O29/O41*100,2) -> 100
A30: Diversos | B30: 9 | C30: =0 -> 0 | D30: =0 -> 0 | E30: =0 -> 0 | F30: =0 -> 0 | G30: =0 -> 0 | H30: =0 -> 0 | I30: =0 -> 0 | J30: =0 -> 0 | ... N30: =0 -> 0 | O30: =SUM(C30:N30) -> 0 | Q30: =CONCATENATE(A30," - ",S30," %") -> Diversos - 0 % | R30: =O30 -> 0 | S30: =ROUND(O30/O41*100,2) -> 0
A31: Aluguel | B31: 13 | C31: =0 -> 0 | D31: =0 -> 0 | E31: =0 -> 0 | F31: =0 -> 0 | G31: =0 -> 0 | H31: =0 -> 0 | I31: =0 -> 0 | J31: =0 -> 0 | ... N31: =0 -> 0 | O31: =SUM(C31:N31) -> 0 | Q31: =CONCATENATE(A31," - ",S31," %") -> Aluguel - 0 % | R31: =O31 -> 0 | S31: =ROUND(O31/O41*100,2) -> 0
A32: Diversos | B32: 10 | C32: =0 -> 0 | D32: =0 -> 0 | E32: =0 -> 0 | F32: =0 -> 0 | G32: =0 -> 0 | H32: =0 -> 0 | I32: =0 -> 0 | J32: =0 -> 0 | ... N32: =0 -> 0 | O32: =SUM(C32:N32) -> 0 | Q32: =CONCATENATE(A32," - ",S32," %") -> Diversos - 0 % | R32: =O32 -> 0 | S32: =ROUND(O32/O41*100,2) -> 0
A33: Saldo do mes Anterior | B33: 1 | C33: =0 -> 0 | D33: =0 -> 0 | E33: =0 -> 0 | F33: =0 -> 0 | G33: =0 -> 0 | H33: =0 -> 0 | I33: =0 -> 0 | J33: =0 -> 0 | ... N33: =0 -> 0 | O33: =SUM(C33:N33) -> 0
C34: =0 -> 0 | D34: =0 -> 0 | E34: =0 -> 0 | F34: =0 -> 0 | G34: =0 -> 0 | H34: =0 -> 0 | I34: =0 -> 0 | J34: =0 -> 0 | ... N34: =0 -> 0 | O34: =SUM(C34:N34) -> 0 | Q34: =A34 -> 0
C35: =0 -> 0 | D35: =0 -> 0 | E35: =0 -> 0 | F35: =0 -> 0 | G35: =0 -> 0 | H35: =0 -> 0 | I35: =0 -> 0 | J35: =0 -> 0 | ... N35: =0 -> 0 | O35: =SUM(C35:N35) -> 0 | Q35: =A35 -> 0
C36: =0 -> 0 | D36: =0 -> 0 | E36: =0 -> 0 | F36: =0 -> 0 | G36: =0 -> 0 | H36: =0 -> 0 | I36: =0 -> 0 | J36: =0 -> 0 | ... N36: =0 -> 0 | O36: =SUM(C36:N36) -> 0 | Q36: =A36 -> 0
C37: =0 -> 0 | D37: =0 -> 0 | E37: =0 -> 0 | F37: =0 -> 0 | G37: =0 -> 0 | H37: =0 -> 0 | I37: =0 -> 0 | J37: =0 -> 0 | ... N37: =0 -> 0 | O37: =SUM(C37:N37) -> 0 | Q37: =A37 -> 0
C38: =0 -> 0 | D38: =0 -> 0 | E38: =0 -> 0 | F38: =0 -> 0 | G38: =0 -> 0 | H38: =0 -> 0 | I38: =0 -> 0 | J38: =0 -> 0 | ... N38: =0 -> 0 | O38: =SUM(C38:N38) -> 0 | Q38: =A38 -> 0
C39: =0 -> 0 | D39: =0 -> 0 | E39: =0 -> 0 | F39: =0 -> 0 | G39: =0 -> 0 | H39: =0 -> 0 | I39: =0 -> 0 | J39: =0 -> 0 | ... N39: =0 -> 0 | O39: =SUM(C39:N39) -> 0 | Q39: =A39 -> 0
A40: Entradas Até Hoje | C40: =IF(AND(YEAR(NOW()) = $A$1,MONTH(NOW()) >= 1), SUMIF($B$29:$B$38,"<=" & DAY(TODAY()),C29:C39), 0) -> 0 | D40: =IF(AND(YEAR(NOW()) = $A$1,MONTH(NOW()) >= 2), SUMIF($B$29:$B$38,"<=" & DAY(TODAY()),D29:D39), 0) -> 0 | E40: =IF(AND(YEAR(NOW()) = $A$1,MONTH(NOW()) >= 3), SUMIF($B$29:$B$38,"<=" & DAY(TODAY()),E29:E39), 0) -> 0 | F40: =IF(AND(YEAR(NOW()) = $A$1,MONTH(NOW()) >= 4), SUMIF($B$29:$B$38,"<=" & DAY(TODAY()),F29:F39), 0) -> 0 | G40: =IF(AND(YEAR(NOW()) = $A$1,MONTH(NOW()) >= 5), SUMIF($B$29:$B$38,"<=" & DAY(TODAY()),G29:G39), 0) -> 0 | H40: =IF(AND(YEAR(NOW()) = $A$1,MONTH(NOW()) >= 6), SUMIF($B$29:$B$38,"<=" & DAY(TODAY()),H29:H39), 0) -> 0 | I40: =IF(AND(YEAR(NOW()) = $A$1,MONTH(NOW()) >= 7), SUMIF($B$29:$B$38,"<=" & DAY(TODAY()),I29:I39), 0) -> 0 | J40: =IF(AND(YEAR(NOW()) = $A$1,MONTH(NOW()) >= 8), SUMIF($B$29:$B$38,"<=" & DAY(TODAY()),J29:J39), 0) -> 0 | K40: =IF(AND(YEAR(NOW()) = $A$1,MONTH(NOW()) >= 9), SUMIF($B$29:$B$38,"<=" & DAY(TODAY()),K29:K39), 0) -> 0 | L40: =IF(AND(YEAR(NOW()) = $A$1,MONTH(NOW()) >= 10), SUMIF($B$29:$B$38,"<=" & DAY(TODAY()),L29:L39), 0) -> 0 | M40: =IF(AND(YEAR(NOW()) = $A$1,MONTH(NOW()) >= 11), SUMIF($B$29:$B$38,"<=" & DAY(TODAY()),M29:M39), 0) -> 0 | N40: =IF(AND(YEAR(NOW()) = $A$1,MONTH(NOW()) >= 12), SUMIF($B$29:$B$38,"<=" & DAY(TODAY()),N29:N39), 0) -> 0 | O40: =SUM(C40:N40) -> 0
A41: Total | C41: =SUM(C29:C39) -> 50 | D41: =SUM(D29:D39) -> 50 | E41: =SUM(E29:E39) -> 50 | F41: =SUM(F29:F39) -> 50 | G41: =SUM(G29:G39) -> 50 | H41: =SUM(H29:H39) -> 50 | I41: =SUM(I29:I39) -> 50 | J41: =SUM(J29:J39) -> 50 | ... N41: =SUM(N29:N39) -> 50 | O41: =SUM(C41:N41) -> 600 | Q41: =A41 -> Total
C43: Jan | D43: Fev | E43: Mar | F43: Abr | G43: Mai | H43: Jun | I43: Jul | J43: Ago | K43: Set | L43: Out | M43: Nov | N43: Dez | O43: Total
...

Sheet Poupança
C1: {=RIGHT(CELL("nome.arquivo"), LEN(CELL("nome.arquivo"))- SEARCH("]",CELL("nome.arquivo")))} -> Despesas
B2: Competencia | C2: Jan | D2: Fev | E2: Mar | F2: Abr | G2: Mai | H2: Jun | I2: Jul | J2: Ago | K2: Set | L2: Out | M2: Nov | N2: Dez
B3: Valor Depositado | C3: =Despesas!C22 -> 0 | D3: =Despesas!D22 -> 0 | E3: =Despesas!E22 -> 0 | F3: =Despesas!F22 -> 0 | G3: =Despesas!G22 -> 0 | H3: =Despesas!H22 -> 0 | I3: =Despesas!I22 -> 0 | J3: =Despesas!J22 -> 0 | ... N3: =Despesas!N22 -> 0
B4: Valor Acumulado | C4: =C3+D11 -> 1 | D4: =(C4*(1+C7))+D3 -> 1.005 | E4: =(D4*(1+D7))+E3 -> 1.010025 | F4: =(E4*(1+E7))+F3 -> 1.0150751 | G4: =(F4*(1+F7))+G3 -> 1.0201505 | H4: =(G4*(1+G7))+H3 -> 1.0252513 | I4: =(H4*(1+H7))+I3 -> 1.0303775 | J4: =(I4*(1+I7))+J3 -> 1.0355294 | K4: =(J4*(1+J7))+K3 -> 1.040707 | ... N4: =(M4*(1+M7))+N3 -> 1.0563958
B5: Saque | C5: =0 -> 0 | D5: =0 -> 0 | E5: =0 -> 0 | F5: =0 -> 0 | G5: =0 -> 0 | H5: =0 -> 0 | I5: =0 -> 0 | J5: =0 -> 0 | ... N5: =0 -> 0 | O5: =SUM(C5:N5) -> 0
B6: Saldo | C6: =C4-C5 -> 1 | D6: =D4-D5 -> 1.005 | E6: =E4-E5 -> 1.010025 | F6: =F4-F5 -> 1.0150751 | G6: =G4-G5 -> 1.0201505 | H6: =H4-H5 -> 1.0252513 | I6: =I4-I5 -> 1.0303775 | J6: =J4-J5 -> 1.0355294 | ... N6: =N4-N5 -> 1.0563958
B7: Remuneração | C7: 0.005 | D7: 0.005 | E7: 0.005 | F7: 0.005 | G7: 0.005 | H7: 0.005 | I7: 0.005 | J7: 0.005 | K7: 0.005 | L7: 0.005 | M7: 0.005 | N7: 0.005
B8: Expectativa | C8: =C6*(1+C7) -> 1.005 | D8: =D6*(1+D7) -> 1.010025 | E8: =E6*(1+E7) -> 1.0150751 | F8: =F6*(1+F7) -> 1.0201505 | G8: =G6*(1+G7) -> 1.0252513 | H8: =H6*(1+H7) -> 1.0303775 | I8: =I6*(1+I7) -> 1.0355294 | J8: =J6*(1+J7) -> 1.040707 | ... N8: =N6*(1+N7) -> 1.0616778
C11: Valor Inicial | D11: 1

Sheet Gastos
B1: {=RIGHT(CELL("nome.arquivo",Gastos!B1:Y1), LEN(CELL("nome.arquivo",Gastos!B1:Y1))- SEARCH("]",CELL("nome.arquivo",Gastos!B1:Y1)))} -> Gastos
B2: dt | C2: ds | D2: Janeiro | G2: Fevereiro | J2: Março | M2: Abril | P2: Maio | S2: Junho | V2: Julho | Y2: Agosto | AB2: Setembro | AE2: Outubro | AH2: Novembro | AK2: Dezembro
D3: =0 -> 0 | G3: =0 -> 0 | J3: =0 -> 0 | M3: =0 -> 0 | P3: =0 -> 0 | S3: =0 -> 0 | V3: =0 -> 0 | Y3: =0 -> 0 | AB3: =0 -> 0 | AE3: =0 -> 0 | AH3: =0 -> 0 | AK3: =0 -> 0
D4: =0 -> 0 | G4: =0 -> 0 | J4: =0 -> 0 | M4: =0 -> 0 | P4: =0 -> 0 | S4: =0 -> 0 | V4: =0 -> 0 | Y4: =0 -> 0 | AB4: =0 -> 0 | AE4: =0 -> 0 | AH4: =0 -> 0 | AK4: =0 -> 0
D5: =0 -> 0 | G5: =0 -> 0 | J5: =0 -> 0 | M5: =0 -> 0 | P5: =0 -> 0 | S5: =0 -> 0 | V5: =0 -> 0 | Y5: =0 -> 0 | AB5: =0 -> 0 | AE5: =0 -> 0 | AH5: =0 -> 0 | AK5: =0 -> 0
D6: =0 -> 0 | G6: =0 -> 0 | J6: =0 -> 0 | M6: =0 -> 0 | P6: =0 -> 0 | S6: =0 -> 0 | V6: =0 -> 0 | Y6: =0 -> 0 | AB6: =0 -> 0 | AE6: =0 -> 0 | AH6: =0 -> 0 | AK6: =0 -> 0
D7: =0 -> 0 | G7: =0 -> 0 | J7: =0 -> 0 | M7: =0 -> 0 | P7: =0 -> 0 | S7: =0 -> 0 | V7: =0 -> 0 | Y7: =0 -> 0 | AB7: =0 -> 0 | AE7: =0 -> 0 | AH7: =0 -> 0 | AK7: =0 -> 0
D8: =0 -> 0 | G8: =0 -> 0 | J8: =0 -> 0 | M8: =0 -> 0 | P8: =0 -> 0 | S8: =0 -> 0 | V8: =0 -> 0 | Y8: =0 -> 0 | AB8: =0 -> 0 | AE8: =0 -> 0 | AH8: =0 -> 0 | AK8: =0 -> 0
D9: =0 -> 0 | G9: =0 -> 0 | J9: =0 -> 0 | M9: =0 -> 0 | P9: =0 -> 0 | S9: =0 -> 0 | V9: =0 -> 0 | Y9: =0 -> 0 | AB9: =0 -> 0 | AE9: =0 -> 0 | AH9: =0 -> 0 | AK9: =0 -> 0 | AU9: 631.35
D10: =0 -> 0 | G10: =0 -> 0 | J10: =0 -> 0 | M10: =0 -> 0 | P10: =0 -> 0 | S10: =0 -> 0 | V10: =0 -> 0 | Y10: =0 -> 0 | AB10: =0 -> 0 | AE10: =0 -> 0 | AH10: =0 -> 0 | AK10: =0 -> 0 | AU10: 489.05
D11: =0 -> 0 | G11: =0 -> 0 | J11: =0 -> 0 | M11: =0 -> 0 | P11: =0 -> 0 | S11: =0 -> 0 | V11: =0 -> 0 | Y11: =0 -> 0 | AB11: =0 -> 0 | AE11: =0 -> 0 | AH11: =0 -> 0 | AK11: =0 -> 0 | AT11: Jogos | AU11: 24.16
D12: =0 -> 0 | G12: =0 -> 0 | J12: =0 -> 0 | M12: =0 -> 0 | P12: =0 -> 0 | S12: =0 -> 0 | V12: =0 -> 0 | Y12: =0 -> 0 | AB12: =0 -> 0 | AE12: =0 -> 0 | AH12: =0 -> 0 | AK12: =0 -> 0 | AT12: Saldo do outro | AU12: -8.37
D13: =0 -> 0 | G13: =0 -> 0 | J13: =0 -> 0 | M13: =0 -> 0 | P13: =0 -> 0 | S13: =0 -> 0 | V13: =0 -> 0 | Y13: =0 -> 0 | AB13: =0 -> 0 | AE13: =0 -> 0 | AH13: =0 -> 0 | AK13: =0 -> 0 | AT13: Passagem | AU13: 190.66
D14: =0 -> 0 | G14: =0 -> 0 | J14: =0 -> 0 | M14: =0 -> 0 | P14: =0 -> 0 | S14: =0 -> 0 | V14: =0 -> 0 | Y14: =0 -> 0 | AB14: =0 -> 0 | AE14: =0 -> 0 | AH14: =0 -> 0 | AK14: =0 -> 0 | AT14: Santander | AU14: 100
D15: =0 -> 0 | G15: =0 -> 0 | J15: =0 -> 0 | M15: =0 -> 0 | P15: =0 -> 0 | S15: =0 -> 0 | V15: =0 -> 0 | Y15: =0 -> 0 | AB15: =0 -> 0 | AE15: =0 -> 0 | AH15: =0 -> 0 | AK15: =0 -> 0 | AU15: =SUM(AU11:AU14) -> 306.45
D16: =0 -> 0 | G16: =0 -> 0 | J16: =0 -> 0 | M16: =0 -> 0 | P16: =0 -> 0 | S16: =0 -> 0 | V16: =0 -> 0 | Y16: =0 -> 0 | AB16: =0 -> 0 | AE16: =0 -> 0 | AH16: =0 -> 0 | AK16: =0 -> 0
D17: =0 -> 0 | G17: =0 -> 0 | J17: =0 -> 0 | M17: =0 -> 0 | P17: =0 -> 0 | S17: =0 -> 0 | V17: =0 -> 0 | Y17: =0 -> 0 | AB17: =0 -> 0 | AE17: =0 -> 0 | AH17: =0 -> 0 | AK17: =0 -> 0
D18: =0 -> 0 | G18: =0 -> 0 | J18: =0 -> 0 | M18: =0 -> 0 | P18: =0 -> 0 | S18: =0 -> 0 | V18: =0 -> 0 | Y18: =0 -> 0 | AB18: =0 -> 0 | AE18: =0 -> 0 | AH18: =0 -> 0 | AK18: =0 -> 0
D19: =0 -> 0 | G19: =0 -> 0 | J19: =0 -> 0 | M19: =0 -> 0 | P19: =0 -> 0 | S19: =0 -> 0 | V19: =0 -> 0 | Y19: =0 -> 0 | AB19: =0 -> 0 | AE19: =0 -> 0 | AH19: =0 -> 0 | AK19: =0 -> 0
D20: =0 -> 0 | G20: =0 -> 0 | J20: =0 -> 0 | M20: =0 -> 0 | P20: =0 -> 0 | S20: =0 -> 0 | V20: =0 -> 0 | Y20: =0 -> 0 | AB20: =0 -> 0 | AE20: =0 -> 0 | AH20: =0 -> 0 | AK20: =0 -> 0
D21: =0 -> 0 | G21: =0 -> 0 | J21: =0 -> 0 | M21: =0 -> 0 | P21: =0 -> 0 | S21: =0 -> 0 | V21: =0 -> 0 | Y21: =0 -> 0 | AB21: =0 -> 0 | AE21: =0 -> 0 | AH21: =0 -> 0 | AK21: =0 -> 0
D22: =0 -> 0 | G22: =0 -> 0 | J22: =0 -> 0 | M22: =0 -> 0 | P22: =0 -> 0 | S22: =0 -> 0 | V22: =0 -> 0 | Y22: =0 -> 0 | AB22: =0 -> 0 | AE22: =0 -> 0 | AH22: =0 -> 0 | AK22: =0 -> 0
D23: =0 -> 0 | G23: =0 -> 0 | J23: =0 -> 0 | M23: =0 -> 0 | P23: =0 -> 0 | S23: =0 -> 0 | V23: =0 -> 0 | Y23: =0 -> 0 | AB23: =0 -> 0 | AE23: =0 -> 0 | AH23: =0 -> 0 | AK23: =0 -> 0
D24: =0 -> 0 | G24: =0 -> 0 | J24: =0 -> 0 | M24: =0 -> 0 | P24: =0 -> 0 | S24: =0 -> 0 | V24: =0 -> 0 | Y24: =0 -> 0 | AB24: =0 -> 0 | AE24: =0 -> 0 | AH24: =0 -> 0 | AK24: =0 -> 0
D25: =0 -> 0 | G25: =0 -> 0 | J25: =0 -> 0 | M25: =0 -> 0 | P25: =0 -> 0 | S25: =0 -> 0 | V25: =0 -> 0 | Y25: =0 -> 0 | AB25: =0 -> 0 | AE25: =0 -> 0 | AH25: =0 -> 0 | AK25: =0 -> 0
D26: =0 -> 0 | G26: =0 -> 0 | J26: =0 -> 0 | M26: =0 -> 0 | P26: =0 -> 0 | S26: =0 -> 0 | V26: =0 -> 0 | Y26: =0 -> 0 | AB26: =0 -> 0 | AE26: =0 -> 0 | AH26: =0 -> 0 | AK26: =0 -> 0
D27: =0 -> 0 | G27: =0 -> 0 | J27: =0 -> 0 | M27: =0 -> 0 | P27: =0 -> 0 | S27: =0 -> 0 | V27: =0 -> 0 | Y27: =0 -> 0 | AB27: =0 -> 0 | AE27: =0 -> 0 | AH27: =0 -> 0 | AK27: =0 -> 0
... D102: =0 -> 0 | G102: =0 -> 0 | J102: =0 -> 0 | M102: =0 -> 0 | P102: =0 -> 0 | S102: =0 -> 0 | V102: =0 -> 0 | Y102: =0 -> 0 | AB102: =0 -> 0 | AE102: =0 -> 0 | AH102: =0 -> 0 | AK102: =0 -> 0

Sheet Cartão 1
B1: {=RIGHT(CELL("nome.arquivo",'Cartão 1'!B1:Y1), LEN(CELL("nome.arquivo",'Cartão 1'!B1:Y1))- SEARCH("]",CELL("nome.arquivo",'Cartão 1'!B1:Y1)))} -> Cartão 1
B2: Janeiro | D2: Fevereiro | F2: Março | H2: Abril | J2: Maio | L2: Junho | N2: Julho | P2: Agosto | R2: Setembro | T2: Outubro | V2: Novembro | X2: Dezembro
C3: =0 -> 0 | E3: =0 -> 0 | G3: =0 -> 0 | I3: =0 -> 0 | K3: =0 -> 0 | M3: =0 -> 0 | O3: =0 -> 0 | Q3: =0 -> 0 | S3: =0 -> 0 | U3: =0 -> 0 | W3: =0 -> 0 | Y3: =0 -> 0
C4: =0 -> 0 | E4: =0 -> 0 | G4: =0 -> 0 | I4: =0 -> 0 | K4: =0 -> 0 | M4: =0 -> 0 | O4: =0 -> 0 | Q4: =0 -> 0 | S4: =0 -> 0 | U4: =0 -> 0 | W4: =0 -> 0 | Y4: =0 -> 0
C5: =0 -> 0 | E5: =0 -> 0 | G5: =0 -> 0 | I5: =0 -> 0 | K5: =0 -> 0 | M5: =0 -> 0 | O5: =0 -> 0 | Q5: =0 -> 0 | S5: =0 -> 0 | U5: =0 -> 0 | W5: =0 -> 0 | Y5: =0 -> 0
C6: =0 -> 0 | E6: =0 -> 0 | G6: =0 -> 0 | I6: =0 -> 0 | K6: =0 -> 0 | M6: =0 -> 0 | O6: =0 -> 0 | Q6: =0 -> 0 | S6: =0 -> 0 | U6: =0 -> 0 | W6: =0 -> 0 | Y6: =0 -> 0
C7: =0 -> 0 | E7: =0 -> 0 | G7: =0 -> 0 | I7: =0 -> 0 | K7: =0 -> 0 | M7: =0 -> 0 | O7: =0 -> 0 | Q7: =0 -> 0 | S7: =0 -> 0 | U7: =0 -> 0 | W7: =0 -> 0 | Y7: =0 -> 0
C8: =0 -> 0 | E8: =0 -> 0 | G8: =0 -> 0 | I8: =0 -> 0 | K8: =0 -> 0 | M8: =0 -> 0 | O8: =0 -> 0 | Q8: =0 -> 0 | S8: =0 -> 0 | U8: =0 -> 0 | W8: =0 -> 0 | Y8: =0 -> 0
C9: =0 -> 0 | E9: =0 -> 0 | G9: =0 -> 0 | I9: =0 -> 0 | K9: =0 -> 0 | M9: =0 -> 0 | O9: =0 -> 0 | Q9: =0 -> 0 | S9: =0 -> 0 | U9: =0 -> 0 | W9: =0 -> 0 | Y9: =0 -> 0
C10: =0 -> 0 | E10: =0 -> 0 | G10: =0 -> 0 | I10: =0 -> 0 | K10: =0 -> 0 | M10: =0 -> 0 | O10: =0 -> 0 | Q10: =0 -> 0 | S10: =0 -> 0 | U10: =0 -> 0 | W10: =0 -> 0 | Y10: =0 -> 0
C11: =0 -> 0 | E11: =0 -> 0 | G11: =0 -> 0 | I11: =0 -> 0 | K11: =0 -> 0 | M11: =0 -> 0 | O11: =0 -> 0 | Q11: =0 -> 0 | S11: =0 -> 0 | U11: =0 -> 0 | W11: =0 -> 0 | Y11: =0 -> 0
C12: =0 -> 0 | E12: =0 -> 0 | G12: =0 -> 0 | I12: =0 -> 0 | K12: =0 -> 0 | M12: =0 -> 0 | O12: =0 -> 0 | Q12: =0 -> 0 | S12: =0 -> 0 | U12: =0 -> 0 | W12: =0 -> 0 | Y12: =0 -> 0
C13: =0 -> 0 | E13: =0 -> 0 | G13: =0 -> 0 | I13: =0 -> 0 | K13: =0 -> 0 | M13: =0 -> 0 | O13: =0 -> 0 | Q13: =0 -> 0 | S13: =0 -> 0 | U13: =0 -> 0 | W13: =0 -> 0 | Y13: =0 -> 0
C14: =0 -> 0 | E14: =0 -> 0 | G14: =0 -> 0 | I14: =0 -> 0 | K14: =0 -> 0 | M14: =0 -> 0 | O14: =0 -> 0 | Q14: =0 -> 0 | S14: =0 -> 0 | U14: =0 -> 0 | W14: =0 -> 0 | Y14: =0 -> 0
... C102: =0 -> 0 | E102: =0 -> 0 | G102: =0 -> 0 | I102: =0 -> 0 | K102: =0 -> 0 | M102: =0 -> 0 | O102: =0 -> 0 | Q102: =0 -> 0 | S102: =0 -> 0 | U102: =0 -> 0 | W102: =0 -> 0 | Y102: =0 -> 0

Sheet Cartão 2
B1: {=RIGHT(CELL("nome.arquivo",'Cartão 2'!B1:Y1), LEN(CELL("nome.arquivo",'Cartão 2'!B1:Y1))- SEARCH("]",CELL("nome.arquivo",'Cartão 2'!B1:Y1)))} -> Cartão 2
B2: Janeiro | D2: Fevereiro | F2: Março | H2: Abril | J2: Maio | L2: Junho | N2: Julho | P2: Agosto | R2: Setembro | T2: Outubro | V2: Novembro | X2: Dezembro
C3: =0 -> 0 | E3: =0 -> 0 | G3: =0 -> 0 | I3: =0 -> 0 | K3: =0 -> 0 | M3: =0 -> 0 | O3: =0 -> 0 | Q3: =0 -> 0 | S3: =0 -> 0 | U3: =0 -> 0 | W3: =0 -> 0 | Y3: =0 -> 0
C4: =0 -> 0 | E4: =0 -> 0 | G4: =0 -> 0 | I4: =0 -> 0 | K4: =0 -> 0 | M4: =0 -> 0 | O4: =0 -> 0 | Q4: =0 -> 0 | S4: =0 -> 0 | U4: =0 -> 0 | W4: =0 -> 0 | Y4: =0 -> 0
C5: =0 -> 0 | E5: =0 -> 0 | G5: =0 -> 0 | I5: =0 -> 0 | K5: =0 -> 0 | M5: =0 -> 0 | O5: =0 -> 0 | Q5: =0 -> 0 | S5: =0 -> 0 | U5: =0 -> 0 | W5: =0 -> 0 | Y5: =0 -> 0
C6: =0 -> 0 | E6: =0 -> 0 | G6: =0 -> 0 | I6: =0 -> 0 | K6: =0 -> 0 | M6: =0 -> 0 | O6: =0 -> 0 | Q6: =0 -> 0 | S6: =0 -> 0 | U6: =0 -> 0 | W6: =0 -> 0 | Y6: =0 -> 0
C7: =0 -> 0 | E7: =0 -> 0 | G7: =0 -> 0 | I7: =0 -> 0 | K7: =0 -> 0 | M7: =0 -> 0 | O7: =0 -> 0 | Q7: =0 -> 0 | S7: =0 -> 0 | U7: =0 -> 0 | W7: =0 -> 0 | Y7: =0 -> 0
C8: =0 -> 0 | E8: =0 -> 0 | G8: =0 -> 0 | I8: =0 -> 0 | K8: =0 -> 0 | M8: =0 -> 0 | O8: =0 -> 0 | Q8: =0 -> 0 | S8: =0 -> 0 | U8: =0 -> 0 | W8: =0 -> 0 | Y8: =0 -> 0
C9: =0 -> 0 | E9: =0 -> 0 | G9: =0 -> 0 | I9: =0 -> 0 | K9: =0 -> 0 | M9: =0 -> 0 | O9: =0 -> 0 | Q9: =0 -> 0 | S9: =0 -> 0 | U9: =0 -> 0 | W9: =0 -> 0 | Y9: =0 -> 0
C10: =0 -> 0 | E10: =0 -> 0 | G10: =0 -> 0 | I10: =0 -> 0 | K10: =0 -> 0 | M10: =0 -> 0 | O10: =0 -> 0 | Q10: =0 -> 0 | S10: =0 -> 0 | U10: =0 -> 0 | W10: =0 -> 0 | Y10: =0 -> 0
C11: =0 -> 0 | E11: =0 -> 0 | G11: =0 -> 0 | I11: =0 -> 0 | K11: =0 -> 0 | M11: =0 -> 0 | O11: =0 -> 0 | Q11: =0 -> 0 | S11: =0 -> 0 | U11: =0 -> 0 | W11: =0 -> 0 | Y11: =0 -> 0
C12: =0 -> 0 | E12: =0 -> 0 | G12: =0 -> 0 | I12: =0 -> 0 | K12: =0 -> 0 | M12: =0 -> 0 | O12: =0 -> 0 | Q12: =0 -> 0 | S12: =0 -> 0 | U12: =0 -> 0 | W12: =0 -> 0 | Y12: =0 -> 0
C13: =0 -> 0 | E13: =0 -> 0 | G13: =0 -> 0 | I13: =0 -> 0 | K13: =0 -> 0 | M13: =0 -> 0 | O13: =0 -> 0 | Q13: =0 -> 0 | S13: =0 -> 0 | U13: =0 -> 0 | W13: =0 -> 0 | Y13: =0 -> 0
C14: =0 -> 0 | E14: =0 -> 0 | G14: =0 -> 0 | I14: =0 -> 0 | K14: =0 -> 0 | M14: =0 -> 0 | O14: =0 -> 0 | Q14: =0 -> 0 | S14: =0 -> 0 | U14: =0 -> 0 | W14: =0 -> 0 | Y14: =0 -> 0
... C102: =0 -> 0 | E102: =0 -> 0 | G102: =0 -> 0 | I102: =0 -> 0 | K102: =0 -> 0 | M102: =0 -> 0 | O102: =0 -> 0 | Q102: =0 -> 0 | S102: =0 -> 0 | U102: =0 -> 0 | W102: =0 -> 0 | Y102: =0 -> 0

Sheet Informações
B3: saida = [], entrada =[];
B4: const JAN = 67, DEZ = JAN + 12;
B5: for(let cont = JAN; cont < DEZ; cont++){
B6: let letra = String.fromCharCode(cont);
B7: saida.push(`=SE(E(ANO(AGORA()) = $A$1;MÊS(AGORA()) >= ${cont-66}); SOMASE($B$3:$B$25;"<=" & DIA(HOJE());${letra}3:${letra}25); 0 )`);
B8: entrada.push(`=SE(E(ANO(AGORA()) = $A$1;MÊS(AGORA()) >= ${cont-66}); SOMASE($B$30:$B$39;"<=" & DIA(HOJE());${letra}30:${letra}40); 0) `)
B9: }
B10: console.log(saida)
B11: console.log(entrada)
